{
 "cells": [
  {
   "cell_type": "code",
   "execution_count": null,
   "id": "b6675043",
   "metadata": {},
   "outputs": [],
   "source": [
    "from kafka import KafkaConsumer\n",
    "from time import sleep\n",
    "from json import dumps,loads\n",
    "import json\n",
    "from s3fs import S3FileSystem"
   ]
  },
  {
   "cell_type": "code",
   "execution_count": null,
   "id": "076feafa",
   "metadata": {},
   "outputs": [],
   "source": [
    "pip install s3fs"
   ]
  },
  {
   "cell_type": "code",
   "execution_count": null,
   "id": "5f4ed90b",
   "metadata": {},
   "outputs": [],
   "source": [
    "pip install kafka-python boto3 s3fs"
   ]
  },
  {
   "cell_type": "code",
   "execution_count": null,
   "id": "9eeff3ef",
   "metadata": {},
   "outputs": [],
   "source": [
    "consumer = KafkaConsumer(\n",
    "    'demo_testing2',\n",
    "    bootstrap_servers=['3.88.183.247:9092'], #adicionar IP aqui\n",
    "    value_deserializer=lambda x: loads(x.decode('utf-8')))"
   ]
  },
  {
   "cell_type": "code",
   "execution_count": null,
   "id": "eda5a608",
   "metadata": {},
   "outputs": [],
   "source": [
    "for c in consumer:\n",
    "  print(c.value)"
   ]
  },
  {
   "cell_type": "code",
   "execution_count": null,
   "id": "8d60dc6c",
   "metadata": {},
   "outputs": [],
   "source": [
    "s3 = S3FileSystem()"
   ]
  },
  {
   "cell_type": "code",
   "execution_count": null,
   "id": "b32f96cb",
   "metadata": {},
   "outputs": [],
   "source": [
    "for count, i in enumerate(consumer):\n",
    "  print (count)\n",
    "  print (i.value)"
   ]
  },
  {
   "cell_type": "code",
   "execution_count": null,
   "id": "0f135e81",
   "metadata": {},
   "outputs": [],
   "source": [
    "for count, i in enumerate(consumer):\n",
    "    with s3.open(\"s3://trabalho-sd/stock_market_{}.json\".format(count), 'w') as file:\n",
    "        json.dump(i.value, file)"
   ]
  },
  {
   "cell_type": "code",
   "execution_count": null,
   "id": "b4ea6468",
   "metadata": {},
   "outputs": [],
   "source": [
    "import s3fs\n",
    "\n",
    "# Inicialização do S3FileSystem com credenciais\n",
    "s3 = s3fs.S3FileSystem(\n",
    "    key='*****AA66QGOEO5****',\n",
    "    secret='*****UJ55Dc3nOe0jYwQjET9y2PbEDe2VhN****',\n",
    "    client_kwargs={'region_name': 'us-east-1'}\n",
    ")\n"
   ]
  },
  {
   "cell_type": "code",
   "execution_count": 51,
   "id": "8b1f20be",
   "metadata": {},
   "outputs": [],
   "source": [
    "# Inicialização do S3FileSystem\n",
    "s3 = s3fs.S3FileSystem(profile='default')"
   ]
  },
  {
   "cell_type": "code",
   "execution_count": 52,
   "id": "a11e5524",
   "metadata": {},
   "outputs": [
    {
     "name": "stdout",
     "output_type": "stream",
     "text": [
      "Unexpected exception formatting exception. Falling back to standard exception\n"
     ]
    },
    {
     "name": "stderr",
     "output_type": "stream",
     "text": [
      "Traceback (most recent call last):\n",
      "  File \"C:\\Users\\kayok\\AppData\\Local\\Packages\\PythonSoftwareFoundation.Python.3.8_qbz5n2kfra8p0\\LocalCache\\local-packages\\Python38\\site-packages\\IPython\\core\\interactiveshell.py\", line 3508, in run_code\n",
      "    exec(code_obj, self.user_global_ns, self.user_ns)\n",
      "  File \"C:\\Users\\kayok\\AppData\\Local\\Temp\\ipykernel_35440\\1044159469.py\", line 8, in <module>\n",
      "    json.dump(i.value, file)\n",
      "  File \"C:\\Users\\kayok\\AppData\\Local\\Packages\\PythonSoftwareFoundation.Python.3.8_qbz5n2kfra8p0\\LocalCache\\local-packages\\Python38\\site-packages\\fsspec\\spec.py\", line 2033, in close\n",
      "    self.flush(force=True)\n",
      "  File \"C:\\Users\\kayok\\AppData\\Local\\Packages\\PythonSoftwareFoundation.Python.3.8_qbz5n2kfra8p0\\LocalCache\\local-packages\\Python38\\site-packages\\fsspec\\spec.py\", line 1897, in flush\n",
      "    if self._upload_chunk(final=force) is not False:\n",
      "  File \"C:\\Users\\kayok\\AppData\\Local\\Packages\\PythonSoftwareFoundation.Python.3.8_qbz5n2kfra8p0\\LocalCache\\local-packages\\Python38\\site-packages\\s3fs\\core.py\", line 2387, in _upload_chunk\n",
      "  File \"C:\\Users\\kayok\\AppData\\Local\\Packages\\PythonSoftwareFoundation.Python.3.8_qbz5n2kfra8p0\\LocalCache\\local-packages\\Python38\\site-packages\\s3fs\\core.py\", line 2412, in commit\n",
      "  File \"C:\\Users\\kayok\\AppData\\Local\\Packages\\PythonSoftwareFoundation.Python.3.8_qbz5n2kfra8p0\\LocalCache\\local-packages\\Python38\\site-packages\\s3fs\\core.py\", line 2249, in _call_s3\n",
      "  File \"C:\\Users\\kayok\\AppData\\Local\\Packages\\PythonSoftwareFoundation.Python.3.8_qbz5n2kfra8p0\\LocalCache\\local-packages\\Python38\\site-packages\\fsspec\\asyn.py\", line 118, in wrapper\n",
      "    return sync(self.loop, func, *args, **kwargs)\n",
      "  File \"C:\\Users\\kayok\\AppData\\Local\\Packages\\PythonSoftwareFoundation.Python.3.8_qbz5n2kfra8p0\\LocalCache\\local-packages\\Python38\\site-packages\\fsspec\\asyn.py\", line 103, in sync\n",
      "    raise return_result\n",
      "  File \"C:\\Users\\kayok\\AppData\\Local\\Packages\\PythonSoftwareFoundation.Python.3.8_qbz5n2kfra8p0\\LocalCache\\local-packages\\Python38\\site-packages\\fsspec\\asyn.py\", line 56, in _runner\n",
      "    result[0] = await coro\n",
      "  File \"C:\\Users\\kayok\\AppData\\Local\\Packages\\PythonSoftwareFoundation.Python.3.8_qbz5n2kfra8p0\\LocalCache\\local-packages\\Python38\\site-packages\\s3fs\\core.py\", line 364, in _call_s3\n",
      "  File \"C:\\Users\\kayok\\AppData\\Local\\Packages\\PythonSoftwareFoundation.Python.3.8_qbz5n2kfra8p0\\LocalCache\\local-packages\\Python38\\site-packages\\s3fs\\core.py\", line 550, in set_session\n",
      "    raise ValueError('Failed to head path %r: %s' % (path, e))\n",
      "  File \"C:\\Users\\kayok\\AppData\\Local\\Packages\\PythonSoftwareFoundation.Python.3.8_qbz5n2kfra8p0\\LocalCache\\local-packages\\Python38\\site-packages\\aiobotocore\\session.py\", line 25, in __aenter__\n",
      "    self._client = await self._coro\n",
      "  File \"C:\\Users\\kayok\\AppData\\Local\\Packages\\PythonSoftwareFoundation.Python.3.8_qbz5n2kfra8p0\\LocalCache\\local-packages\\Python38\\site-packages\\aiobotocore\\session.py\", line 144, in _create_client\n",
      "    region_name = self._resolve_region_name(region_name, config)\n",
      "  File \"C:\\Users\\kayok\\AppData\\Local\\Packages\\PythonSoftwareFoundation.Python.3.8_qbz5n2kfra8p0\\LocalCache\\local-packages\\Python38\\site-packages\\botocore\\session.py\", line 1021, in _resolve_region_name\n",
      "    region_name = self.get_config_variable('region')\n",
      "  File \"C:\\Users\\kayok\\AppData\\Local\\Packages\\PythonSoftwareFoundation.Python.3.8_qbz5n2kfra8p0\\LocalCache\\local-packages\\Python38\\site-packages\\botocore\\session.py\", line 323, in get_config_variable\n",
      "    return self.get_component('config_store').get_config_variable(\n",
      "  File \"C:\\Users\\kayok\\AppData\\Local\\Packages\\PythonSoftwareFoundation.Python.3.8_qbz5n2kfra8p0\\LocalCache\\local-packages\\Python38\\site-packages\\botocore\\configprovider.py\", line 488, in get_config_variable\n",
      "    return provider.provide()\n",
      "  File \"C:\\Users\\kayok\\AppData\\Local\\Packages\\PythonSoftwareFoundation.Python.3.8_qbz5n2kfra8p0\\LocalCache\\local-packages\\Python38\\site-packages\\botocore\\configprovider.py\", line 694, in provide\n",
      "    value = provider.provide()\n",
      "  File \"C:\\Users\\kayok\\AppData\\Local\\Packages\\PythonSoftwareFoundation.Python.3.8_qbz5n2kfra8p0\\LocalCache\\local-packages\\Python38\\site-packages\\botocore\\configprovider.py\", line 781, in provide\n",
      "    scoped_config = self._session.get_scoped_config()\n",
      "  File \"C:\\Users\\kayok\\AppData\\Local\\Packages\\PythonSoftwareFoundation.Python.3.8_qbz5n2kfra8p0\\LocalCache\\local-packages\\Python38\\site-packages\\botocore\\session.py\", line 422, in get_scoped_config\n",
      "    raise ProfileNotFound(profile=profile_name)\n",
      "botocore.exceptions.ProfileNotFound: The config profile (default) could not be found\n",
      "\n",
      "During handling of the above exception, another exception occurred:\n",
      "\n",
      "Traceback (most recent call last):\n",
      "  File \"C:\\Users\\kayok\\AppData\\Local\\Packages\\PythonSoftwareFoundation.Python.3.8_qbz5n2kfra8p0\\LocalCache\\local-packages\\Python38\\site-packages\\IPython\\core\\interactiveshell.py\", line 2105, in showtraceback\n",
      "    stb = self.InteractiveTB.structured_traceback(\n",
      "  File \"C:\\Users\\kayok\\AppData\\Local\\Packages\\PythonSoftwareFoundation.Python.3.8_qbz5n2kfra8p0\\LocalCache\\local-packages\\Python38\\site-packages\\IPython\\core\\ultratb.py\", line 1396, in structured_traceback\n",
      "    return FormattedTB.structured_traceback(\n",
      "  File \"C:\\Users\\kayok\\AppData\\Local\\Packages\\PythonSoftwareFoundation.Python.3.8_qbz5n2kfra8p0\\LocalCache\\local-packages\\Python38\\site-packages\\IPython\\core\\ultratb.py\", line 1287, in structured_traceback\n",
      "    return VerboseTB.structured_traceback(\n",
      "  File \"C:\\Users\\kayok\\AppData\\Local\\Packages\\PythonSoftwareFoundation.Python.3.8_qbz5n2kfra8p0\\LocalCache\\local-packages\\Python38\\site-packages\\IPython\\core\\ultratb.py\", line 1140, in structured_traceback\n",
      "    formatted_exception = self.format_exception_as_a_whole(etype, evalue, etb, number_of_lines_of_context,\n",
      "  File \"C:\\Users\\kayok\\AppData\\Local\\Packages\\PythonSoftwareFoundation.Python.3.8_qbz5n2kfra8p0\\LocalCache\\local-packages\\Python38\\site-packages\\IPython\\core\\ultratb.py\", line 1055, in format_exception_as_a_whole\n",
      "    frames.append(self.format_record(record))\n",
      "  File \"C:\\Users\\kayok\\AppData\\Local\\Packages\\PythonSoftwareFoundation.Python.3.8_qbz5n2kfra8p0\\LocalCache\\local-packages\\Python38\\site-packages\\IPython\\core\\ultratb.py\", line 955, in format_record\n",
      "    frame_info.lines, Colors, self.has_colors, lvals\n",
      "  File \"C:\\Users\\kayok\\AppData\\Local\\Packages\\PythonSoftwareFoundation.Python.3.8_qbz5n2kfra8p0\\LocalCache\\local-packages\\Python38\\site-packages\\IPython\\core\\ultratb.py\", line 778, in lines\n",
      "    return self._sd.lines\n",
      "  File \"C:\\Users\\kayok\\AppData\\Local\\Packages\\PythonSoftwareFoundation.Python.3.8_qbz5n2kfra8p0\\LocalCache\\local-packages\\Python38\\site-packages\\stack_data\\utils.py\", line 145, in cached_property_wrapper\n",
      "    value = obj.__dict__[self.func.__name__] = self.func(obj)\n",
      "  File \"C:\\Users\\kayok\\AppData\\Local\\Packages\\PythonSoftwareFoundation.Python.3.8_qbz5n2kfra8p0\\LocalCache\\local-packages\\Python38\\site-packages\\stack_data\\core.py\", line 734, in lines\n",
      "    pieces = self.included_pieces\n",
      "  File \"C:\\Users\\kayok\\AppData\\Local\\Packages\\PythonSoftwareFoundation.Python.3.8_qbz5n2kfra8p0\\LocalCache\\local-packages\\Python38\\site-packages\\stack_data\\utils.py\", line 145, in cached_property_wrapper\n",
      "    value = obj.__dict__[self.func.__name__] = self.func(obj)\n",
      "  File \"C:\\Users\\kayok\\AppData\\Local\\Packages\\PythonSoftwareFoundation.Python.3.8_qbz5n2kfra8p0\\LocalCache\\local-packages\\Python38\\site-packages\\stack_data\\core.py\", line 681, in included_pieces\n",
      "    pos = scope_pieces.index(self.executing_piece)\n",
      "  File \"C:\\Users\\kayok\\AppData\\Local\\Packages\\PythonSoftwareFoundation.Python.3.8_qbz5n2kfra8p0\\LocalCache\\local-packages\\Python38\\site-packages\\stack_data\\utils.py\", line 145, in cached_property_wrapper\n",
      "    value = obj.__dict__[self.func.__name__] = self.func(obj)\n",
      "  File \"C:\\Users\\kayok\\AppData\\Local\\Packages\\PythonSoftwareFoundation.Python.3.8_qbz5n2kfra8p0\\LocalCache\\local-packages\\Python38\\site-packages\\stack_data\\core.py\", line 660, in executing_piece\n",
      "    return only(\n",
      "  File \"C:\\Users\\kayok\\AppData\\Local\\Packages\\PythonSoftwareFoundation.Python.3.8_qbz5n2kfra8p0\\LocalCache\\local-packages\\Python38\\site-packages\\executing\\executing.py\", line 116, in only\n",
      "    raise NotOneValueFound('Expected one value, found 0')\n",
      "executing.executing.NotOneValueFound: Expected one value, found 0\n"
     ]
    }
   ],
   "source": [
    "# Loop para consumir mensagens do Kafka e salvar no S3\n",
    "for count, i in enumerate(consumer):\n",
    "    # Nome do arquivo no bucket S3\n",
    "    s3_file_path = f\"s3://trabalho-sd/stock_market_{count}.json\"\n",
    "    \n",
    "    # Escrevendo o conteúdo no S3\n",
    "    with s3.open(s3_file_path, 'w') as file:\n",
    "        json.dump(i.value, file)\n",
    "    \n",
    "    print(f\"Arquivo {s3_file_path} enviado com sucesso!\")"
   ]
  }
 ],
 "metadata": {
  "kernelspec": {
   "display_name": "Python 3",
   "language": "python",
   "name": "python3"
  },
  "language_info": {
   "codemirror_mode": {
    "name": "ipython",
    "version": 3
   },
   "file_extension": ".py",
   "mimetype": "text/x-python",
   "name": "python",
   "nbconvert_exporter": "python",
   "pygments_lexer": "ipython3",
   "version": "3.8.10"
  }
 },
 "nbformat": 4,
 "nbformat_minor": 5
}
